<?xml version="1.0" ?>
<!-- =================================================================================== -->
<!-- |    This document was autogenerated by xacro from ur5.urdf.xacro                 | -->
<!-- |    EDITING THIS FILE BY HAND IS NOT RECOMMENDED                                 | -->
<!-- =================================================================================== -->
<robot name="ur_robot">
  <!--
    NOTE: the macro defined in this file is NOT part of the public API of this
          package. Users CANNOT rely on this file being available, or stored in
          this location. Nor can they rely on the existence of the macro.
  -->
  <transmission name="shoulder_pan_trans">
    <type>transmission_interface/SimpleTransmission</type>
    <joint name="shoulder_pan_joint">
      <hardwareInterface>hardware_interface/EffortJointInterface</hardwareInterface>
    </joint>
    <actuator name="shoulder_pan_motor">
      <mechanicalReduction>1</mechanicalReduction>
    </actuator>
  </transmission>
  <transmission name="shoulder_lift_trans">
    <type>transmission_interface/SimpleTransmission</type>
    <joint name="shoulder_lift_joint">
      <hardwareInterface>hardware_interface/EffortJointInterface</hardwareInterface>
    </joint>
    <actuator name="shoulder_lift_motor">
      <mechanicalReduction>1</mechanicalReduction>
    </actuator>
  </transmission>
  <transmission name="elbow_trans">
    <type>transmission_interface/SimpleTransmission</type>
    <joint name="elbow_joint">
      <hardwareInterface>hardware_interface/EffortJointInterface</hardwareInterface>
    </joint>
    <actuator name="elbow_motor">
      <mechanicalReduction>1</mechanicalReduction>
    </actuator>
  </transmission>
  <transmission name="wrist_1_trans">
    <type>transmission_interface/SimpleTransmission</type>
    <joint name="wrist_1_joint">
      <hardwareInterface>hardware_interface/EffortJointInterface</hardwareInterface>
    </joint>
    <actuator name="wrist_1_motor">
      <mechanicalReduction>1</mechanicalReduction>
    </actuator>
  </transmission>
  <transmission name="wrist_2_trans">
    <type>transmission_interface/SimpleTransmission</type>
    <joint name="wrist_2_joint">
      <hardwareInterface>hardware_interface/EffortJointInterface</hardwareInterface>
    </joint>
    <actuator name="wrist_2_motor">
      <mechanicalReduction>1</mechanicalReduction>
    </actuator>
  </transmission>
  <transmission name="wrist_3_trans">
    <type>transmission_interface/SimpleTransmission</type>
    <joint name="wrist_3_joint">
      <hardwareInterface>hardware_interface/EffortJointInterface</hardwareInterface>
    </joint>
    <actuator name="wrist_3_motor">
      <mechanicalReduction>1</mechanicalReduction>
    </actuator>
  </transmission>
  <!-- links: main serial chain -->
  <link name="base_link"/>
  <link name="base_link_inertia">
    <visual>
      <origin rpy="0 0 3.141592653589793" xyz="0 0 0"/>
      <geometry>
        <mesh filename="package://ur_description/meshes/ur5e/visual/base.dae"/>
      </geometry>
      <material name="LightGrey">
        <color rgba="0.7 0.7 0.7 1.0"/>
      </material>
    </visual>
    <collision>
      <origin rpy="0 0 3.141592653589793" xyz="0 0 0"/>
      <geometry>
        <mesh filename="package://ur_description/meshes/ur5e/collision/base.stl"/>
      </geometry>
    </collision>
    <inertial>
      <mass value="4.0"/>
      <origin rpy="0 0 0" xyz="0 0 0"/>
      <inertia ixx="0.00443333156" ixy="0.0" ixz="0.0" iyy="0.00443333156" iyz="0.0" izz="0.0072"/>
    </inertial>
  </link>
  <link name="shoulder_link">
    <visual>
      <origin rpy="0 0 3.141592653589793" xyz="0 0 0"/>
      <geometry>
        <mesh filename="package://ur_description/meshes/ur5e/visual/shoulder.dae"/>
      </geometry>
      <material name="LightGrey">
        <color rgba="0.7 0.7 0.7 1.0"/>
      </material>
    </visual>
    <collision>
      <origin rpy="0 0 3.141592653589793" xyz="0 0 0"/>
      <geometry>
        <mesh filename="package://ur_description/meshes/ur5e/collision/shoulder.stl"/>
      </geometry>
    </collision>
    <inertial>
      <mass value="3.7"/>
      <origin rpy="0 0 0" xyz="0 0 0"/>
      <inertia ixx="0.010267495893" ixy="0.0" ixz="0.0" iyy="0.010267495893" iyz="0.0" izz="0.00666"/>
    </inertial>
  </link>
  <link name="upper_arm_link">
    <visual>
      <origin rpy="1.5707963267948966 0 -1.5707963267948966" xyz="0 0 0.138"/>
      <geometry>
        <mesh filename="package://ur_description/meshes/ur5e/visual/upperarm.dae"/>
      </geometry>
      <material name="LightGrey">
        <color rgba="0.7 0.7 0.7 1.0"/>
      </material>
    </visual>
    <collision>
      <origin rpy="1.5707963267948966 0 -1.5707963267948966" xyz="0 0 0.138"/>
      <geometry>
        <mesh filename="package://ur_description/meshes/ur5e/collision/upperarm.stl"/>
      </geometry>
    </collision>
    <inertial>
      <mass value="8.393"/>
      <origin rpy="0 1.5707963267948966 0" xyz="-0.2125 0.0 0.138"/>
      <inertia ixx="0.1338857818623325" ixy="0.0" ixz="0.0" iyy="0.1338857818623325" iyz="0.0" izz="0.0151074"/>
    </inertial>
  </link>
  <link name="forearm_link">
    <visual>
      <origin rpy="1.5707963267948966 0 -1.5707963267948966" xyz="0 0 0.007"/>
      <geometry>
        <mesh filename="package://ur_description/meshes/ur5e/visual/forearm.dae"/>
      </geometry>
      <material name="LightGrey">
        <color rgba="0.7 0.7 0.7 1.0"/>
      </material>
    </visual>
    <collision>
      <origin rpy="1.5707963267948966 0 -1.5707963267948966" xyz="0 0 0.007"/>
      <geometry>
        <mesh filename="package://ur_description/meshes/ur5e/collision/forearm.stl"/>
      </geometry>
    </collision>
    <inertial>
      <mass value="2.275"/>
      <origin rpy="0 1.5707963267948966 0" xyz="-0.1961 0.0 0.007"/>
      <inertia ixx="0.031209355099586295" ixy="0.0" ixz="0.0" iyy="0.031209355099586295" iyz="0.0" izz="0.004095"/>
    </inertial>
  </link>
  <link name="wrist_1_link">
    <visual>
      <!-- TODO: Move this to a parameter -->
      <origin rpy="1.5707963267948966 0 0" xyz="0 0 -0.127"/>
      <geometry>
        <mesh filename="package://ur_description/meshes/ur5e/visual/wrist1.dae"/>
      </geometry>
      <material name="LightGrey">
        <color rgba="0.7 0.7 0.7 1.0"/>
      </material>
    </visual>
    <collision>
      <origin rpy="1.5707963267948966 0 0" xyz="0 0 -0.127"/>
      <geometry>
        <mesh filename="package://ur_description/meshes/ur5e/collision/wrist1.stl"/>
      </geometry>
    </collision>
    <inertial>
      <mass value="1.219"/>
      <origin rpy="0 0 0" xyz="0 0 0"/>
      <inertia ixx="0.0025598989760400002" ixy="0.0" ixz="0.0" iyy="0.0025598989760400002" iyz="0.0" izz="0.0021942"/>
    </inertial>
  </link>
  <link name="wrist_2_link">
    <visual>
      <origin rpy="0 0 0" xyz="0 0 -0.0997"/>
      <geometry>
        <mesh filename="package://ur_description/meshes/ur5e/visual/wrist2.dae"/>
      </geometry>
      <material name="LightGrey">
        <color rgba="0.7 0.7 0.7 1.0"/>
      </material>
    </visual>
    <collision>
      <origin rpy="0 0 0" xyz="0 0 -0.0997"/>
      <geometry>
        <mesh filename="package://ur_description/meshes/ur5e/collision/wrist2.stl"/>
      </geometry>
    </collision>
    <inertial>
      <mass value="1.219"/>
      <origin rpy="0 0 0" xyz="0 0 0"/>
      <inertia ixx="0.0025598989760400002" ixy="0.0" ixz="0.0" iyy="0.0025598989760400002" iyz="0.0" izz="0.0021942"/>
    </inertial>
  </link>
  <link name="wrist_3_link">
    <visual>
      <origin rpy="1.5707963267948966 0 0" xyz="0 0 -0.0989"/>
      <geometry>
        <mesh filename="package://ur_description/meshes/ur5e/visual/wrist3.dae"/>
      </geometry>
      <material name="LightGrey">
        <color rgba="0.7 0.7 0.7 1.0"/>
      </material>
    </visual>
    <collision>
      <origin rpy="1.5707963267948966 0 0" xyz="0 0 -0.0989"/>
      <geometry>
        <mesh filename="package://ur_description/meshes/ur5e/collision/wrist3.stl"/>
      </geometry>
    </collision>
    <inertial>
      <mass value="0.1879"/>
      <origin rpy="0 0 0" xyz="0.0 0.0 -0.0229"/>
      <inertia ixx="9.890410052167731e-05" ixy="0.0" ixz="0.0" iyy="9.890410052167731e-05" iyz="0.0" izz="0.0001321171875"/>
    </inertial>
  </link>
  <!-- joints: main serial chain -->
  <joint name="base_link-base_link_inertia" type="fixed">
    <parent link="base_link"/>
    <child link="base_link_inertia"/>
    <!-- 'base_link' is REP-103 aligned (so X+ forward), while the internal
           frames of the robot/controller have X+ pointing backwards.
           Use the joint between 'base_link' and 'base_link_inertia' (a dummy
           link/frame) to introduce the necessary rotation over Z (of pi rad).
      -->
    <origin rpy="3.141592653589793 0 0" xyz="0 0 0"/>
  </joint>
  <joint name="shoulder_pan_joint" type="revolute">
    <parent link="base_link_inertia"/>
    <child link="shoulder_link"/>
    <origin rpy="0 0 0" xyz="0 0 0.1625"/>
    <axis xyz="0 0 1"/>
    <limit effort="150.0" lower="-6.14" upper="6.14" velocity="3.14"/>
    <dynamics damping="0" friction="0"/>
  </joint>
  <joint name="shoulder_lift_joint" type="revolute">
    <parent link="shoulder_link"/>
    <child link="upper_arm_link"/>
    <origin rpy="1.570796327 0 0" xyz="0 0 0"/>
    <axis xyz="0 0 1"/>
    <limit effort="150.0" lower="-3.14" upper="0" velocity="3.14"/>
    <dynamics damping="0" friction="0"/>
  </joint>
  <joint name="elbow_joint" type="revolute">
    <parent link="upper_arm_link"/>
    <child link="forearm_link"/>
    <origin rpy="0 0 0" xyz="-0.425 0 0"/>
    <axis xyz="0 0 1"/>
    <limit effort="150.0" lower="-3.14" upper="3.14" velocity="3.14"/>
    <dynamics damping="0" friction="0"/>
  </joint>
  <joint name="wrist_1_joint" type="revolute">
    <parent link="forearm_link"/>
    <child link="wrist_1_link"/>
    <origin rpy="0 0 0" xyz="-0.3922 0 0.1333"/>
    <axis xyz="0 0 1"/>
    <limit effort="28.0" lower="-6.28" upper="6.28" velocity="3.14"/>
    <dynamics damping="0" friction="0"/>
  </joint>
  <joint name="wrist_2_joint" type="revolute">
    <parent link="wrist_1_link"/>
    <child link="wrist_2_link"/>
    <origin rpy="1.570796327 0 0" xyz="0 -0.0997 -2.044881182297852e-11"/>
    <axis xyz="0 0 1"/>
    <limit effort="28.0" lower="-6.28" upper="6.28" velocity="3.14"/>
    <dynamics damping="0" friction="0"/>
  </joint>
  <joint name="wrist_3_joint" type="revolute">
    <parent link="wrist_2_link"/>
    <child link="wrist_3_link"/>
    <origin rpy="1.570796326589793 3.141592653589793 3.141592653589793" xyz="0 0.0996 -2.042830148012698e-11"/>
    <axis xyz="0 0 1"/>
    <limit effort="28.0" lower="-6.28" upper="6.28" velocity="3.14"/>
    <dynamics damping="0" friction="0"/>
  </joint>
  <!-- ROS-Industrial 'base' frame: base_link to UR 'Base' Coordinates transform -->
  <link name="base"/>
  <joint name="base_link-base_fixed_joint" type="fixed">
    <!-- Note the rotation over Z of pi radians: as base_link is REP-103
           aligned (ie: has X+ forward, Y+ left and Z+ up), this is needed
           to correctly align 'base' with the 'Base' coordinate system of
           the UR controller.
      -->
    <origin rpy="0 0 3.141592653589793" xyz="0 0 0"/>
    <parent link="base_link"/>
    <child link="base"/>
  </joint>
  <!-- ROS-Industrial 'flange' frame: attachment point for EEF models -->
  <link name="flange"/>
  <joint name="wrist_3-flange" type="fixed">
    <parent link="wrist_3_link"/>
    <child link="flange"/>
    <origin rpy="0 -1.5707963267948966 -1.5707963267948966" xyz="0 0 0"/>
  </joint>
  <!-- ROS-Industrial 'tool0' frame: all-zeros tool frame -->
  <link name="tool0"/>
  <joint name="flange-tool0" type="fixed">
    <!-- default toolframe: X+ left, Y+ up, Z+ front -->
    <origin rpy="1.5707963267948966 0 1.5707963267948966" xyz="0 0 0"/>
    <parent link="flange"/>
    <child link="tool0"/>
  </joint>
  <!-- fixed frames for collisions (potential fields)-->
  <link name="upper_arm_link_middle"/>
  <joint name="upper_arm_link_middle_fixed_joint" type="fixed">
    <origin rpy="0 0 0" xyz="-0.2125 0 0.13"/>
    <parent link="upper_arm_link"/>
    <child link="upper_arm_link_middle"/>
  </joint>
  <link name="forearm_link_middle"/>
  <joint name="forearm_link_middle_fixed_joint" type="fixed">
    <origin rpy="0 0 0" xyz="-0.2125 0.0 0.0"/>
    <parent link="forearm_link"/>
    <child link="forearm_link_middle"/>
  </joint>
  <link name="forearm_link_end"/>
  <joint name="forearm_link_end_fixed_joint" type="fixed">
    <origin rpy="0 0 0" xyz="-0.425 0 0"/>
    <parent link="forearm_link"/>
    <child link="forearm_link_end"/>
  </joint>
  <link name="gripper_base_down">
    <inertial>
      <origin rpy="0 0 0" xyz="0.0 0.0 0.0"/>
      <mass value="1.0"/>
      <inertia ixx="0.01" ixy="0.0" ixz="0.0" iyy="0.01" iyz="0.0" izz="0.01"/>
    </inertial>
    <visual>
      <origin rpy="-1.5707963267948966 0 0" xyz="0.1 0 0"/>
    </visual>
    <collision>
      <origin rpy="-1.5707963267948966 0 0" xyz="0 0 0"/>
    </collision>
  </link>
  <link name="gripper_base">
    <visual>
      <origin rpy="-1.5707963267948966 0 0" xyz="0.2275 0 0 "/>
      <geometry>
        <mesh filename="package://gripper_description/meshes/gripper_base_up.stl" scale="0.001 0.008 0.001"/>
      </geometry>
    </visual>
    <collision>
      <origin rpy="-1.5707963267948966 0 0" xyz="0.2275 0 0"/>
      <geometry>
        <mesh filename="package://gripper_description/meshes/gripper_base_up.stl" scale="0.001 0.008 0.001"/>
      </geometry>
    </collision>
  </link>
  <joint name="flange" type="fixed">
    <origin rpy="0 0 0" xyz="0 0 0.06"/>
    <parent link="gripper_base"/>
    <child link="gripper_base_down"/>
  </joint>
  <joint name="fixed_ee_gripper" type="fixed">
    <origin rpy="0 0 0" xyz="0 0 0.12"/>
    <parent link="gripper_base"/>
    <child link="ee_gripper"/>
  </joint>
  <link name="ee_gripper"/>
  <joint name="hand_1_joint" type="fixed">
    <parent link="gripper_base_down"/>
    <child link="hand_1_link"/>
    <axis xyz="0 -1 0"/>
    <origin rpy="-1.5707963267948966 0 0" xyz="0.0  -0.03 0.05"/>
    <limit effort="50" lower="0" upper="3.14" velocity="10.0"/>
  </joint>
  <link name="hand_1_link">
    <inertial>
      <origin xyz="0.0 0.0 0.0"/>
      <mass value="0.05"/>
      <inertia ixx="0.001" ixy="0.0" ixz="0.0" iyy="0.001" iyz="0.0" izz="0.001"/>
    </inertial>
    <visual>
      <origin rpy="0 0 0" xyz="0 0.05 0.03"/>
      <geometry>
        <mesh filename="package://gripper_description/meshes/finger.stl" scale="0.001 0.001 0.001"/>
      </geometry>
    </visual>
    <collision>
      <origin rpy="0 0 0" xyz="0 0.05 0.03"/>
      <geometry>
        <mesh filename="package://gripper_description/meshes/finger.stl" scale="0.001 0.001 0.001"/>
      </geometry>
    </collision>
  </link>
  <transmission name="hand_1_trans">
    <type>transmission_interface/SimpleTransmission</type>
    <joint name="hand_1_joint">
      <hardwareInterface>hardware_interface/EffortJointInterface</hardwareInterface>
    </joint>
    <actuator name="hand_1_pan_motor">
      <mechanicalReduction>1</mechanicalReduction>
    </actuator>
  </transmission>
  <gazebo reference="hand_1_link">
    <collision name="hand_1_link_collision">
      <surface>
        <friction>
          <torsional>
            <coefficient>10.0</coefficient>
            <use_patch_radius>true</use_patch_radius>
            <patch_radius>0.05</patch_radius>
          </torsional>
        </friction>
        <contact>
          <poissons_ratio>0.5</poissons_ratio>
          <elastic_modulus>1e8</elastic_modulus>
        </contact>
      </surface>
    </collision>
    <mu1>10</mu1>
    <mu2>10</mu2>
    <kp>1000000.0</kp>
    <kd>10.0</kd>
    <fdir1>0 0 1</fdir1>
    <minDepth>0.001</minDepth>
    <maxVel>0.0</maxVel>
    <maxContacts>1</maxContacts>
    <material>Gazebo/RedBright</material>
  </gazebo>
  <joint name="hand_2_joint" type="fixed">
    <parent link="gripper_base_down"/>
    <child link="hand_2_link"/>
    <axis xyz="0 -1 0"/>
    <origin rpy="-1.5707963267948966 0 2.0943951023931953" xyz="0.02598 0.015 0.05"/>
    <limit effort="50" lower="0" upper="3.14" velocity="10.0"/>
  </joint>
  <link name="hand_2_link">
    <inertial>
      <origin xyz="0.0 0.0 0.0"/>
      <mass value="0.05"/>
      <inertia ixx="0.001" ixy="0.0" ixz="0.0" iyy="0.001" iyz="0.0" izz="0.001"/>
    </inertial>
    <visual>
      <origin rpy="0 0 0" xyz="0 0.05 0.03"/>
      <geometry>
        <mesh filename="package://gripper_description/meshes/finger.stl" scale="0.001 0.001 0.001"/>
      </geometry>
    </visual>
    <collision>
      <origin rpy="0 0 0" xyz="0 0.05 0.03"/>
      <geometry>
        <mesh filename="package://gripper_description/meshes/finger.stl" scale="0.001 0.001 0.001"/>
      </geometry>
    </collision>
  </link>
  <transmission name="hand_2_trans">
    <type>transmission_interface/SimpleTransmission</type>
    <joint name="hand_2_joint">
      <hardwareInterface>hardware_interface/EffortJointInterface</hardwareInterface>
    </joint>
    <actuator name="hand_2_pan_motor">
      <mechanicalReduction>1</mechanicalReduction>
    </actuator>
  </transmission>
  <gazebo reference="hand_2_link">
    <collision name="hand_2_link_collision">
      <surface>
        <friction>
          <torsional>
            <coefficient>10.0</coefficient>
            <use_patch_radius>true</use_patch_radius>
            <patch_radius>0.05</patch_radius>
          </torsional>
        </friction>
        <contact>
          <poissons_ratio>0.5</poissons_ratio>
          <elastic_modulus>1e8</elastic_modulus>
        </contact>
      </surface>
    </collision>
    <mu1>10</mu1>
    <mu2>10</mu2>
    <kp>1000000.0</kp>
    <kd>10.0</kd>
    <fdir1>0 0 1</fdir1>
    <minDepth>0.001</minDepth>
    <maxVel>0.0</maxVel>
    <maxContacts>1</maxContacts>
    <material>Gazebo/RedBright</material>
  </gazebo>
  <joint name="hand_3_joint" type="fixed">
    <parent link="gripper_base_down"/>
    <child link="hand_3_link"/>
    <axis xyz="0 -1 0"/>
    <origin rpy="-1.5707963267948966 0 -2.0943951023931953" xyz="-0.02598 0.015 0.05"/>
    <limit effort="50" lower="0" upper="3.14" velocity="10.0"/>
  </joint>
  <link name="hand_3_link">
    <inertial>
      <origin xyz="0.0 0.0 0.0"/>
      <mass value="0.05"/>
      <inertia ixx="0.001" ixy="0.0" ixz="0.0" iyy="0.001" iyz="0.0" izz="0.001"/>
    </inertial>
    <visual>
      <origin rpy="0 0 0" xyz="0 0.05 0.03"/>
      <geometry>
        <mesh filename="package://gripper_description/meshes/finger.stl" scale="0.001 0.001 0.001"/>
      </geometry>
    </visual>
    <collision>
      <origin rpy="0 0 0" xyz="0 0.05 0.03"/>
      <geometry>
        <mesh filename="package://gripper_description/meshes/finger.stl" scale="0.001 0.001 0.001"/>
      </geometry>
    </collision>
  </link>
  <transmission name="hand_3_trans">
    <type>transmission_interface/SimpleTransmission</type>
    <joint name="hand_3_joint">
      <hardwareInterface>hardware_interface/EffortJointInterface</hardwareInterface>
    </joint>
    <actuator name="hand_3_pan_motor">
      <mechanicalReduction>1</mechanicalReduction>
    </actuator>
  </transmission>
  <gazebo reference="hand_3_link">
    <collision name="hand_3_link_collision">
      <surface>
        <friction>
          <torsional>
            <coefficient>10.0</coefficient>
            <use_patch_radius>true</use_patch_radius>
            <patch_radius>0.05</patch_radius>
          </torsional>
        </friction>
        <contact>
          <poissons_ratio>0.5</poissons_ratio>
          <elastic_modulus>1e8</elastic_modulus>
        </contact>
      </surface>
    </collision>
    <mu1>10</mu1>
    <mu2>10</mu2>
    <kp>1000000.0</kp>
    <kd>10.0</kd>
    <fdir1>0 0 1</fdir1>
    <minDepth>0.001</minDepth>
    <maxVel>0.0</maxVel>
    <maxContacts>1</maxContacts>
    <material>Gazebo/RedBright</material>
  </gazebo>
  <gazebo>
    <plugin filename="libgazebo_grasp_fix.so" name="gazebo_grasp_fix">
      <arm>
        <arm_name>ur5</arm_name>
        <palm_link> wrist_3_link  </palm_link>
        <gripper_link> hand_1_link </gripper_link>
        <gripper_link> hand_2_link </gripper_link>
        <gripper_link> hand_3_link </gripper_link>
      </arm>
      <forces_angle_tolerance>100</forces_angle_tolerance>
      <update_rate>500</update_rate>
      <grip_count_threshold>4</grip_count_threshold>
      <max_grip_count>20</max_grip_count>
      <release_tolerance>0.01</release_tolerance>
      <disable_collisions_on_attach>true</disable_collisions_on_attach>
      <contact_topic>__default_topic__</contact_topic>
    </plugin>
  </gazebo>
  <joint name="gripper_robot_joint" type="fixed">
    <parent link="tool0"/>
    <child link="gripper_base"/>
    <origin rpy="0 0 3.14" xyz="0 0 0"/>
  </joint>
  <!--
    Attach the Gazebo model to Gazebo's world frame.

    Note: if you're looking to integrate a UR into a larger scene and need
    to add EEFs or other parts, DO NOT change this file or the 'world' link
    here. Create a NEW xacro instead and decide whether you need to add
    a 'world' link there.
  -->
  <link name="world"/>
  <joint name="world_joint" type="fixed">
    <parent link="world"/>
    <child link="base_link"/>
    <origin rpy="0 0 0" xyz="0 0 0"/>
  </joint>
  <!-- Configure self collision properties per link -->
  <gazebo reference="shoulder_link">
    <selfCollide>true</selfCollide>
  </gazebo>
  <gazebo reference="upper_arm_link">
    <selfCollide>true</selfCollide>
  </gazebo>
  <gazebo reference="forearm_link">
    <selfCollide>true</selfCollide>
  </gazebo>
  <gazebo reference="wrist_1_link">
    <selfCollide>true</selfCollide>
  </gazebo>
  <gazebo reference="wrist_3_link">
    <selfCollide>true</selfCollide>
  </gazebo>
  <gazebo reference="wrist_2_link">
    <selfCollide>true</selfCollide>
  </gazebo>
  <gazebo reference="ee_link">
    <selfCollide>true</selfCollide>
  </gazebo>
  <!-- fix me https://answers.gazebosim.org//question/15095/gazebo-contact-sensor-added-to-a-robot-link-in-urdf-file-is-not-working-as-expected/-->
  <!--gazebo reference="$(arg prefix)wrist_3_link">
		<kp>1000000.0</kp>
		<kd>100.0</kd>
		<mu1>1.0</mu1>
		<mu2>1.0</mu2>
		<maxVel>1.0</maxVel>
		<maxContacts>1</maxContacts>
		<sensor name="ee_contact_sensor" type="contact">
			<always_on>true</always_on>
			<update_rate>250.0</update_rate>
			<contact>
				<collision>$(arg prefix)wrist_3_link_collision_collision</collision>
			</contact>
		        <plugin name="gazebo_ros_bumper_controller" filename="libgazebo_ros_bumper.so">
				<bumperTopicName>/ur5/wrench</bumperTopicName>	
				<frameName>$(arg prefix)wrist_3_link</frameName>		
		        	<robotNamespace>ur5</robotNamespace>
			</plugin>
		</sensor>
	</gazebo-->
  <!--
      Inject Gazebo ROS Control plugin, which allows us to use ros_control
      controllers to control the virtual robot hw.
    -->
  <gazebo>
    <plugin filename="libgazebo_ros_control.so" name="gazebo_ros_controller_manager">
      <robotNamespace>/ur5</robotNamespace>
      <!--TODO1 change this with prefix when you use 2 robots     -->
      <robotSimType>gazebo_ros_control/DefaultRobotHWSim</robotSimType>
      <legacyModeNS>true</legacyModeNS>
    </plugin>
  </gazebo>
</robot>
